Workbook

Sheet Instruções de uso
B1: @dropdown
D2: Carteira "Nasser" Family Investimentos
A7: Planilha de Rentabilidade
A10: Orientações e Sugestões de Utilização
A12: Preencha a planilha com os dados do investimento. Coloque suas próprias informações para adaptar a planilha à sua vida;
A14: ATENÇÃO: não altere as células da cor CINZA;
A16: Busque as informações em suas corretoras e/ou bancos.
A18: A planilha serve como BASE para calcular o retorno de suas aplicações financeiras. Você pode fazer modificações se desejar.
A20: IMPORTANTE: leia as instruções de uso da planilha.

Sheet NCs

Sheet BenchMarK
A2: MES A MES
A3: DATA | B3: 01/21 | C3: 02/21 | D3: 03/21 | E3: 04/21 | F3: 05/21 | G3: 06/21 | H3: 07/21 | I3: 08/21 | J3: 44440 | K3: 10/21
A5: BENCHMARK IBOV | B5: -3.32 | C5: -0.0437 | D5: 0.06 | E5: 0.0194 | F5: 0.061583 | G5: 0.0046 | H5: -0.039438 | I5: -0.0247 | J5: -6.57
A7: CARTEIRA NASSER FAMILY | B7: 0 | C7: 0 | D7: ='Planilha de Rentabilidade'!AO67 -> -1 | E7: ='Planilha de Rentabilidade'!AP67 | F7: =+'Planilha de Rentabilidade'!AQ67 | G7: 0 | J7: ='Planilha de Rentabilidade'!AU67 | K7: ='Planilha de Rentabilidade'!AV67
A11: BenchMarket Acumulado | G11: C.N.F. mensal
B12: IBOV | C12: C.N.M. | E12: CDI - DI
A13: 01/24 | B13: 0.1256 | C13: 0 | E13: 0.0116 | G13: ='Planilha de Rentabilidade'!AI7 -> 0.0082489277
A14: 02/24 | B14: 0.0395 | C14: 0 | E14: 0.0066 | G14: ='Planilha de Rentabilidade'!AI15 -> -0.0089058383
A15: 03/24 | B15: 0 | C15: 0 | E15: 0 | G15: 0
A16: 04/24 | B16: 0 | C16: 0 | E16: 0 | G16: 0
A17: 05/24 | B17: 0 | C17: 0 | E17: 0 | G17: 0
A18: 06/24 | B18: 0 | C18: 0 | E18: 0 | G18: 0
A19: 07/24 | B19: 0 | C19: 0 | E19: 0 | G19: 0
A20: 08/24 | B20: 0 | C20: 0 | E20: 0 | G20: 0
A21: 09/24 | B21: 0 | C21: 0 | E21: 0 | G21: 0
A22: 10/24 | B22: 0 | C22: 0 | E22: 0 | G22: 0
A23: 11/24 | B23: 0 | E23: 0 | G23: 0
A24: 12/24 | B24: 0 | E24: 0 | G24: 0

Sheet % de Alocação da Carteira 01_25
B2: ANALISE % de Alocação da Carteira "Nasser Family"p/ Produto Financeiro (01/2024) | M2: ALOCAÇÃO % COMPACTA
E3: =+SUM(E4:E14) -> 1
B4: CAIXA | D4: =+'Planilha de Rentabilidade'!E6 -> -333138 | E4: =D4/$E$15 -> -0.10559144 | L4: IPCA + | M4: =SUM(D5:D7) -> 416980.73 | N4: =M4/$M$15 -> 0.13216624
B5: TESOURO IPCA+2035 | D5: =+'Planilha de Rentabilidade'!Q6 -> 63463 | E5: =D5/$E$15 -> 0.020115236 | M5: 0 | N5: =M5/$M$15 -> 0
B6: DEBENTURE | D6: =+'Planilha de Rentabilidade'!P6 -> 231658.11 | E6: =D6/$E$15 -> 0.073426368 | M6: 0 | N6: =M6/$M$15 -> 0
B7: CRI CRA | D7: ='Planilha de Rentabilidade'!O6 -> 121859.62 | E7: =D7/$E$15 -> 0.038624632 | L7: LCA | M7: =+D11 -> 0 | N7: =M7/$M$15 -> 0
B8: TESOURO SELIC + LFTS11 | D8: ='Planilha de Rentabilidade'!C6+'Planilha de Rentabilidade'!D6+'Planilha de Rentabilidade'!S6+'Planilha de Rentabilidade'!F6 -> 186765.12 | E8: =D8/$E$15 -> 0.059197083 | L8: RENDA FIXA | M8: =D8+D12+D13 -> 973746.18 | N8: =M8/$M$15 -> 0.30863865
B9: MOEDAS | D9: ='Planilha de Rentabilidade'!L6 -> 89125.92 | E9: =D9/$E$15 -> 0.028249357 | L9: GOLD+$$ | M9: =+D10 -> 339349 | N9: =M9/$M$15 -> 0.10756008
B10: GOLD+$ | D10: ='Planilha de Rentabilidade'!M6 -> 339349 | E10: =D10/$E$15 -> 0.10756008 | L10: MOEDAS | M10: =D9 -> 89125.92 | N10: =M10/$M$15 -> 0.028249357
B11: LCA | D11: =0 -> 0 | E11: =D11/$E$15 -> 0 | N11: =M11/$M$15 -> 0
B12: FUNDO DI | D12: ='Planilha de Rentabilidade'!G6+'Planilha de Rentabilidade'!I6+'Planilha de Rentabilidade'!J6 -> 541210.38 | E12: =D12/$E$15 -> 0.17154207 | L12: CAIXA | M12: =+D4 -> -333138 | N12: =M12/$M$15 -> -0.10559144
B13: CDB DI | D13: ='Planilha de Rentabilidade'!H6+'Planilha de Rentabilidade'!K6 -> 245770.68 | E13: =D13/$E$15 -> 0.077899489 | N13: =M13/$M$15 -> 0
B14: RENDA VARIAVEL | D14: =B33 -> 1668907.8 | E14: =D14/$E$15 -> 0.52897712 | L14: Renda Variavel | M14: =D14 -> 1668907.8 | N14: =M14/$M$15 -> 0.52897712
C15: Total da Carteira Nasser Family ==> | E15: =SUM(D4:D14) -> 3154971.6 | M15: =SUM(M4:M14) -> 3154971.6 | N15: =SUM(N4:N14) -> 1
B18: ANALISE % Alocação da Carteira "Nasser Family" RENDA VARIAVEL(01/2024)
C19: % Renda Variavel Alocadas por Setor
B20: =+'Planilha de Rentabilidade'!Z6+'Planilha de Rentabilidade'!W6 -> 0 | C20: =B20/$B$33 -> 0 | D20: IRON ORE
B21: 0 | C21: =B21/$B$33 -> 0 | D21: SOJA
B22: =+'Planilha de Rentabilidade'!AF6+'Planilha de Rentabilidade'!U6 -> 996194.32 | C22: =B22/$B$33 -> 0.59691393 | D22: Electric Vehicle
B23: =+'Planilha de Rentabilidade'!V6+'Planilha de Rentabilidade'!AD6 -> 151536 | C23: =B23/$B$33 -> 0.090799503 | D23: MELI
B24: =+'Planilha de Rentabilidade'!AE6 -> 0 | C24: =B24/$B$33 -> 0 | D24: LITHIUM
B25: 0 | C25: =B25/$B$33 -> 0 | D25: ENERGIA
B26: =0 -> 0 | C26: =B26/$B$33 -> 0 | D26: CELULOSE
B27: =+'Planilha de Rentabilidade'!AA6 -> 0 | C27: =B27/$B$33 -> 0 | D27: Saude
B28: =+'Planilha de Rentabilidade'!R6 -> 176421 | C28: =B28/$B$33 -> 0.10571045 | D28: AURA
B29: =+'Planilha de Rentabilidade'!X6+'Planilha de Rentabilidade'!AC6 -> 174080.5 | C29: =B29/$B$33 -> 0.10430804 | D29: AMD
B30: ='Planilha de Rentabilidade'!T6+'Planilha de Rentabilidade'!AG6 -> 0 | C30: =B30/$B$33 -> 0 | D30: APPLE
B31: ='Planilha de Rentabilidade'!N6+'Planilha de Rentabilidade'!AH6 -> 0 | C31: =B31/$B$33 -> 0 | D31: INTEL
B32: =+'Planilha de Rentabilidade'!AB6 -> 170676 | C32: =B32/$B$33 -> 0.10226808 | D32: WEGE
B33: =SUM(B20:B32) -> 1668907.8 | C33: =B33/$B$33 -> 1

Sheet Planilha de Rentabilidade
A1: Mês | B1: Descrição | C1: Tesouro Alexa | D1: Tesouro Nasser | E1: SALDOS | F1: LFTS11 BTG ALEXA | G1: FUNDO BTG DIGITAL SELIC FIRF | H1: CDB NU NASSER | I1: BB FUNDO-RF LP HIGH | J1: FUNDO BTG CDB PLUS FIRF CRPR | K1: CDB - SANTANDER | L1: MOEDAS - WISE | M1: GOLD + CASH | N1: INTEL NASSER - ITLC34 | O1: CRI OPEA IPCA+6,63%2040 BTG | P1: DEBENTURE IGUA RIO IRJS15 IPCA+7,60% | Q1: TESOURO ALEXA IPCA+ 2029 | R1: AURA33 NASSER BTG | S1: LFT-S11 BTG NASSER | T1: AAPL34 BTG NASSER | U1: TSLA34 - BTG NASSER | V1: MELI34 BTG NASSER | W1: CMIN3 NASSER BTG | X1: A1MD34 AMD BTG ALEXA | Y1: ASML34 BTG NASSER | Z1: VALE3 NASSER BTG | AA1: HAPV3 HAPVIDA BTG ALEXA | AB1: WEGE3 - BTG NASSER | AC1: AMD A1MD34 BTG NASSER | AD1: MELI34 BTG ALEXA | AE1: SIGMA BTG ALEXA | AF1: TESLA ALEXA BTG | AG1: AAPL34 ALEXA BTG | AH1: ITLC34 ALEXA BTG | AI1: Patrimônio | AL1: @
A2: 45658 | B2: Valor em 31/12/2024 | C2: =+(12508.62+20736.77)*0+(12535.93+20782.67)*0+(12556.6+20817.08)*0+(12598.75+20886.49)*0+(12620+20921)*0+(12641.27+20955.72)*0+(12648.27+20967.15) -> 33615.42 | D2: =+149296.91*0+149622.35*0+149874.58*0+150042.05*0+150211.96*0+150383.65*0+150641.47*0+150891.01*0+150973.61 -> 150973.61 | E2: =+(+157896.94+105619.23)*0+(120284.75-11217.78+110000)*0+(-1007-21656+110152)*0+(-4041.8-24669+106500+114581+33638)*0+(-44568.88+115309-40000)*0+(-63001-40260+112378)*0+(-59384-42365+112378)*0+(+21258.2+1620)*0+(+43575-6839)*0+(-57105-14912+9135+36122)*0+((-5942.97-57120)+(+36122))*0+(-66864-443+20000+12736)*0+((-73278-36511)+(-38726-28000))*0+((-39639-28000-36468)+(-14720-13392))*0+((-39639-28000-36468-59711+12751)+(-13392+3746+80545+41069))*0+((-39639-28000-36468-59711+12751)+(121057-9655))*0+((+300-28000+531-68711+12751)+(+11656+3322+62397+258))*0+((+300-28000+531+875-68711+12766)+(+80895.41+3529))*0+(-43253.36+120881-512)*0+((+77627+25980+5593+6472-4170)+(-55911+531+12766+466))*0+((+77627+25980-4170+5593)+(+985+12766+408+531+475-55911))*0+((+103386.01+1406+6472)+(-71761+985+17191+408+531+475))*0+((+9897+60942+6444)+(+231+17191+855+475))*0+((+70826+6444)+(+231+855+475))*0+((-11781+6444)+(+231+855+475))*0+((-14446+6444)+(+231+475+355))*0+((-55637-46658)+(700+231+355+475)) -> -100534 | F2: =+(+350+50)*145.4 -> 58160 | G2: =+113120.91*0+113364.9*0+113560.98*0+113620.29*0+113810.75*0+113873.59*0+114070.01*0+114317.49*0+114378.69 -> 114378.69 | H2: =+17191*0+17201.19*0+17211.08 -> 17211.08 | I2: =+185984.49*0+186360.05*0+186683.67*0+187308.72*0+187415*0+187520.82*0+187721.71*0+187830.99*0+187931.6*0+188042.95 -> 188042.95 | J2: =+229637.76*0+230273.34*0+230656.49*0+230783.54*0+231164.99*0+231291.84*0+231674.36*0+232190.08*0+232331.89 -> 232331.89 | K2: =+224902*0+225149.4*0+225521.99*0+225770.72*0+226893.42*0+227519.55 -> 227519.55 | L2: =+122965.86*0+146740.18*0+148753*0+130221*0+(129920-18962.43)*0+111978*0+(112056.62-14410)*0+95950*0+96233*0+98142*0+97927*0+98118*0+98337*0+86133*0+86140.21*0+(72134.11*0+72063.5+2000-13366.37)*0+60723.67*0+61075*0+60621.02*0+60020.65*0+59982.56 -> 59982.56 | M2: =+(+163088.45+23393.68+12308.53+18823.14+18962.43)*0+(252047.43+13833.97+13366.37)*0+284245.72 -> 284245.72 | N2: 0 | O2: =+120000*0+120114.45*0+120177.45*0+120242.46*0+120323.39*0+120433.9*0+120655.21*0+120755.05*0+120825.34*0+120875.65 -> 120875.65 | P2: =+227708.9*0+228061.55*0+228240*0+228459.98*0+228547.9*0+228768.26*0+229102.07*0+229358.02*0+229561.48*0+229663.28 -> 229663.28 | Q2: =+62076.13*0+62422.89*0+62000.18*0+61926.54*0+62123.52*0+62516.1*0+62619.35 -> 62619.35 | R2: =+(+2250+600)*91.03 -> 259435.5 | S2: =+(+404+5+45-200)*145.4 -> 36931.6 | T2: 0 | U2: =+(+10345-500)*77.52 -> 763184.4 | V2: =+1700*92.22 -> 156774 | W2: 0 | X2: =+(+270+140)*147 -> 60270 | Y2: 0 | Z2: =+(+2700-500-500+2100-600-500-500-700-500)*71.96 -> 71960 | AA2: =+(+900+800+600+300+100+700)*14.73 -> 50082 | AB2: =+(+3100+100+1000)*48.51 -> 203742 | AC2: =+(+700+110+200)*147 -> 148470 | AD2: =+450*92.22 -> 41499 | AE2: 0 | AF2: =+(+1300+660)*77.52 -> 151939.2 | AG2: 0 | AH2: 0 | AI2: =SUM(C2:AH2) -> 3623373.5
B3: Investimento (+) | C3: 0 | D3: 0 | E3: 0 | F3: =+50*145.35+37*145.27+13*145.6 -> 14535.29 | G3: 0 | H3: 0 | I3: 0 | J3: 0 | K3: 0 | L3: =+4000+6500+6500+8000+10000+4500+17000+10000+5000+10000+5000+6000 -> 92500 | M3: =+24568+15566+14970 -> 55104 | O3: 0 | P3: 0 | Q3: 0 | R3: 0 | S3: 0 | T3: 0 | U3: =+300*73.01 + 300*72.21 + 200*72.01 +300*71.76 +99*71.11 + 100*70.74 + 100*71.02 + 99*70.16 + 99*70.36 + 30*71.09 + 36*71.21 + 30*70.91 + 10*71.29 + 10*71.23 + 100*70.16 + 50*70.53 -> 133414.63 | V3: =+100*93.15 -> 9315 | W3: 0 | X3: 0 | Y3: 0 | Z3: 0 | AA3: =+500*13.43 + 100*13.5 + 100*13.5 + 100*13.5 + 100*13.51 + 100*13.4 + 100*13.42+1000*13.37 -> 28168 | AB3: 0 | AC3: 0 | AD3: 0 | AE3: 0 | AF3: =+20*71.39 + 20*71.09 + 20*71.18 + 20*71.02 + 20*70.91 + 20*71.14 + 10*71.23 + 10*71.3 + 10*71.05 + 80*70.73 -> 16328.8 | AG3: 0 | AH3: 0 | AI3: =SUM(C3:AH3) -> 349365.72 | AW3: 44227 | AX3: 44255
B4: Resgate (-) | C4: 0 | D4: 0 | E4: =+E6-E2 -> -232604 | F4: =-100*145.75 - 100*145.75 - 100*145.75 - 100*145.74 - 100*145.75 -> -72874 | G4: 0 | H4: =-950-100-200-400-200 -> -1850 | I4: 0 | J4: 0 | K4: 0 | L4: =-3158-24568-15566-14970 -> -58262 | M4: 0 | N4: 0 | O4: 0 | P4: 0 | Q4: 0 | R4: =-100*96.7 - 100*95.88 - 100*95.5 - 17*95.72 - 83*95.81 - 100*96.7 -100*93.27 - 100*93.28 -50*104.53 - 50*104.59 - 50*108.01 - 50*108.1-100*114.36-100*114.49-30*114.99-30*115.22-30*115.42 -30*124.81 - 30*124.88 -50*115.44 -> -134490.57 | S4: =+(-200*145.75 -16*145.82 - 38*145.83) -> -37024.66 | T4: 0 | U4: 0 | V4: =-100*94.12 - 50*94.1 -15*93.93 - 85*93.93 - 1*94.28 - 15*94.28 - 84*94.28 - 100*94.43 - 100*94.51 - 8*94.65 - 30*94.65 - 62*94.65 -> -61297 | W4: 0 | X4: =0 -> 0 | Y4: 0 | Z4: =-100*75.88 - 100*75.86 - 100*75.85 - 100*75.83 - 100*75.92 - 100*75.81 - 100*75.96 - 100*75.94 - 100*75.9 -100*75.35 -> -75830 | AA4: =-100*12.94 - 100*12.94 - 100*12.94 - 200*12.94 - 200*12.94 - 200*12.94 - 200*12.94 - 300*12.94 - 600*12.94 - 1000*12.94 - 1000*12.94 - 1500*12.94 -> -71170 | AB4: =-100*49.47 - 100*49.35 -100*51.86 - 100*51.95 - 100*51.95 - 100*51.96 - 100*51.98 - 100*52.01 - 100*52.06 -> -46259 | AC4: =-3*166.18-17*166.18-20*166.23-20*166.29-20*166.34-20*166.38-20*166.39-20*166.54-25*172.34 - 25*172.14 - 25*172.22 -50*156.92 - 50*157.36 -> -51918.5 | AE4: 0 | AF4: 0 | AG4: 0 | AH4: 0 | AI4: =SUM(C4:AH4) -> -843579.73 | AJ4: =SUM(AI3:AI4) -> -494214.01
B5: Rebecimento de proventos (-) | C5: 0 | D5: 0 | E5: 0 | F5: 0 | G5: 0 | H5: 0 | I5: 0 | J5: 0 | K5: 0 | L5: 0 | M5: 0 | N5: 0 | O5: 0 | P5: 0 | Q5: 0 | S5: 0 | T5: 0 | U5: 0 | V5: 0 | W5: 0 | X5: 0 | Y5: 0 | Z5: 0 | AA5: 0 | AB5: 0 | AC5: 0 | AD5: 0 | AE5: 0 | AF5: 0 | AG5: 0 | AH5: 0 | AI5: =SUM(C5:AH5) -> 0 | AJ5: =SUM(AI2:AI5) -> 3129159.4
B6: Valor final no mês | C6: =+(12648.27+20967.15)*0+(12732.53+21106.26)*0+(12753.71+21141.27)*0+(21211.38+12796.6) -> 34007.98 | D6: =+150973.61*0+151566.61*0+151999.69*0+152254.52*0+152757.14 -> 152757.14 | E6: =+((-34158-68280)+(+1593+475-29768+6509))*0+(+4649)*0+((68069.38-14802)+(+794-63403.25))*0+((-23272-18115)-(29197))*0+((+3383.54-18115)+(-29197))*0+((-16940-18127)+(-29197-58481.52))*0+((+35059-18127)+(-29197-58481))*0+((+24450-15988)+(-29197-69781))*0+(-179460-52554)+(-29197-35766-36161) -> -333138 | F6: =+(+400+87+13-500)*145.46 -> 0 | G6: =+114441.83*0+114761.23*0+115075.87*0+115334.66*0+115725.16 -> 115725.16 | H6: =+17230.859*0+16275*0+15710*0+15765*0+5146.48+10424.2 -> 15570.68 | I6: =+188146.5*0+188703.88*0+189306.57*0+189751.27*0+190427.39 -> 190427.39 | J6: =+232459.53*0+233099.7*0+233748.6*0+234265.56*0+235057.83 -> 235057.83 | K6: =+227644.99*0+228399.04*0+230200 -> 230200 | L6: =+59961.56*0+(60202.83+35500-24568)*0+(+68739+17000-15566+10000)*0+(79573.81+5000-14970)*0+69408*0+78973*0+(78572+5000+6000)*0+89303*0+88531*0+89125.92 -> 89125.92 | M6: =+284245+24568+15566+14970 -> 339349 | O6: =+120875.65*0+121168.16*0+121367.79*0+121570.9*0+121859.62 -> 121859.62 | P6: =+229663.28*0+230256.42*0+230660.74*0+230920.8*0+231658.11 -> 231658.11 | Q6: =+62619.35*0+62612.83*0+62649.84*0+63463 -> 63463 | R6: =+(+2850-500-200-200-200-90-60-50)*113.82 -> 176421 | S6: =+(254-200-54)*145.46 -> 0 | T6: 0 | U6: =+(+9845+800+300+763)*71.69 -> 839346.52 | V6: =+(+1700+100-150-500)*94.71 -> 108916.5 | W6: 0 | X6: =+(+410)*159.3 -> 65313 | Y6: 0 | Z6: =+(+1000-900-100)*72.21 -> 0 | AA6: =+(+3400+1100+1000-5500)*13 -> 0 | AB6: =+(+4200-200-700)*51.72 -> 170676 | AC6: =+(+1010-140-75-100)*156.5 -> 108767.5 | AD6: =+450*94.71 -> 42619.5 | AE6: 0 | AF6: =+(+1960+230)*71.62 -> 156847.8 | AG6: 0 | AH6: 0 | AI6: =SUM(C6:AH6) -> 3154971.6 | AJ6: =AJ5-AI6 -> -25812.21 | AO6: "Nasser Family BTG" Investimentos 2026
B7: Rentabilidade (ao mês) | C7: =IFERROR(IF(C6=0,(-C4/C2)-1,C8),"") -> 0.011677974 | D7: =IFERROR(IF(D6=0,(-D4/D2)-1,D8),"") -> 0.011813522 | E7: =IFERROR(IF(E6=0,(-E4/E2)-1,E8),"") -> 0 | F7: =IFERROR(IF(F6=0,(-F4/F2)-1,F8),"") -> 0.25299175 | G7: =IFERROR(IF(G6=0,(-G4/G2)-1,G8),"") -> 0.011772036 | H7: =IFERROR(IF(H6=0,(-H4/H2)-1,H8),"") -> 0.013644874 | I7: =IFERROR(IF(I6=0,(-I4/(I2+I3))-1,I8),"") -> 0.012680295 | J7: =IFERROR(IF(J6=0,(-J4/(J2+J3))-1,J8),"") -> 0.011732957 | K7: =IFERROR(IF(K6=0,(-K4/(K2+K3))-1,K8),"") -> 0.011781185 | L7: =IFERROR(IF(L6=0,(-L4/(L2+L3))-1,L8),"") -> -0.054071426 | M7: =IFERROR(IF(M6=0,(-M4/(M2+M3))-1,M8),"") -> -2.121705e-06 | N7: =IFERROR(IF(N6=0,(-N4/(N2+N3))-1,N8),"") | O7: =IFERROR(IF(O6=0,(-O4/(O2+O3))-1,O8),"") -> 0.0081403492 | P7: =IFERROR(IF(P6=0,(-P4/(P2+P3))-1,P8),"") -> 0.0086858901 | ... AH7: =IFERROR(IF(AH6=0,(-AH4/(AH2+AH3))-1,AH8),"") | AI7: =IFERROR(IF(AI6=0,(-AI4/AI2)-1,AI8),"") -> 0.0082489277 | AJ7: =AI6*AI7 -> 26025.133
B8: Não mexer | C8: =IFERROR(IF(AND(C2<>0,C6=""),"",(C6/(C2+C3+C4+C5))-1),"") -> 0.011677974 | D8: =IFERROR(IF(AND(D2<>0,D6=""),"",(D6/(D2+D3+D4+D5))-1),"") -> 0.011813522 | E8: =IFERROR(IF(AND(E2<>0,E6=""),"",(E6/(E2+E3+E4+E5))-1),"") -> 0 | F8: =IFERROR(IF(AND(F2<>0,F6=""),"",(F6/(F2+F3+F4+F5))-1),"") -> -1 | G8: =IFERROR(IF(AND(G2<>0,G6=""),"",(G6/(G2+G3+G4+G5))-1),"") -> 0.011772036 | H8: =IFERROR(IF(AND(H2<>0,H6=""),"",(H6/(H2+H3+H4+H5))-1),"") -> 0.013644874 | I8: =IFERROR(IF(AND(I2<>0,I6=""),"",(I6/(I2+I3+I4+I5))-1),"") -> 0.012680295 | J8: =IFERROR(IF(AND(J2<>0,J6=""),"",(J6/(J2+J3+J4+J5))-1),"") -> 0.011732957 | ... AI8: =IFERROR(IF(AND(AI2<>0,AI6=""),"",(AI6/(AI2+AI3+AI4+AI5))-1),"") -> 0.0082489277
B9: Ativo/PL | C9: =IFERROR(C6/$AI$6,"") -> 0.010779171 | D9: =IFERROR(D6/$AI$6,"") -> 0.048417912 | E9: =IFERROR(E6/$AI$6,"") -> -0.10559144 | F9: =IFERROR(F6/$AI$6,"") -> 0 | G9: =IFERROR(G6/$AI$6,"") -> 0.036680254 | H9: =IFERROR(H6/$AI$6,"") -> 0.0049352837 | I9: =IFERROR(I6/$AI$6,"") -> 0.060357877 | J9: =IFERROR(J6/$AI$6,"") -> 0.074503944 | ... AI9: =IFERROR(AI6/$AI$6,"") -> 1 | AJ9: =AI6-AI2 -> -468401.8 | AK9: =AI6/AI2-1 -> -0.12927229
A10: 45689 | B10: Valor-base | C10: =IF(C14="","",C6) -> 34007.98 | D10: =IF(D14="","",D6) -> 152757.14 | E10: =IF(E14="","",E6) -> -333138 | F10: =IF(F14="","",F6) -> 0 | G10: =IF(G14="","",G6) -> 115725.16 | H10: =IF(H14="","",H6) -> 15570.68 | I10: =IF(I14="","",I6) -> 190427.39 | J10: =IF(J14="","",J6) -> 235057.83 | ... AH10: =IF(AH14="","",AH6) -> 0 | AI10: =SUM(C10:AH10) -> 3154971.6
B11: Investimento (+) | C11: 0 | D11: 0 | E11: 0 | F11: =+300*147.59 +40*147.75 + 40*147.75 + 1*147.74 + 1*147.74 + 6*147.74 + 11*147.74 + 11*147.74 + 23*147.74 + 27*147.74 + 40*147.74 + 40*147.74 + 13*147.73 + 27*147.73 + 40*147.71 + 40*147.71 + 40*147.71 -> 103369.8 | G11: 0 | H11: 0 | I11: 0 | J11: 0 | K11: 0 | L11: =+10000+10000+15000+10000+5000+12000 -> 62000 | M11: =+20734.59*0+18674.97+9941.48 -> 28616.45 | N11: =+50*39.12 + 50*39.06 + 50*39 + 50*38.93 + 50*38.89 + 50*38.85 + 50*38.81 + 50*38.81 + 50*38.81 + 50*38.68 + 4*38.62 + 46*38.62 + 50*38.61 + 1*38.6 + 49*38.6 + 50*38.55 + 50*38.54 -> 29094 | O11: 0 | P11: 0 | Q11: 0 | R11: =100*120.14 + 100*120.02 + 100*119.81 -> 35997 | S11: =+70*147.89+70*147.92 -> 20706.7 | T11: 0 | U11: =+50*66.9+50*66.88 -> 6689 | V11: =+200*84.65 + 200*85.62 -> 34054 | W11: 0 | X11: =+16*132.03 + 16*132.13 + 16*132.23 + 16*132.33 + 16*132.43 + 16*132.53 + 16*132.65 + 16*132.73 + 16*132.83 + 16*132.93 -> 21197.12 | Y11: 0 | Z11: 0 | AA11: 0 | AB11: 0 | AC11: =+374*131.64 -> 49233.36 | AD11: =+50*84.87 + 50*84.73 + 50*84.65 + 50*83.68 -> 16896.5 | AE11: 0 | AF11: 0 | AG11: 0 | AH11: 0 | AI11: =SUM(C11:AH11) -> 407853.93
B12: Resgate (-) | C12: 0 | D12: 0 | E12: =+E14-E10 -> 262280 | H12: 0 | I12: 0 | J12: 0 | K12: 0 | L12: =-519.15-20734.59-18674.97-9941.48 -> -49870.19 | M12: 0 | N12: 0 | O12: 0 | P12: 0 | Q12: 0 | R12: =-50*108.62 - 50*109.31 - 50*108.06 - 25*109.09 - 60*110.02 - 60*110.1 - 60*110.29 - 60*110.74 - 60*110.47 - 60*111.01-1*125.34 - 1*125.34 - 2*125.34 - 5*125.34 - 7*125.34 - 10*125.34 - 24*125.34 - 50*125.41 - 50*125.47 - 50*125.53 - 50*127.67 - 65*127.78 - 50*127.82 - 50*127.98 -100*129.43 - 13*129.79 - 87*129.79 - 100*129.92 -> -150265.25 | S12: 0 | T12: 0 | U12: 0 | V12: 0 | W12: 0 | X12: 0 | Y12: 0 | Z12: 0 | AA12: 0 | AB12: =-300*53.02 - 300*53.01 - 100*53.01 - 200*53.04 -300*53.02 - 300*53.01 - 100*53.01 - 200*53.04-200*52.42 - 200*52.46 - 200*52.4 - 200*52.42 - 100*52.4 - 100*52.43 - 200*52.47 - 200*52.38 - 200*52.44 - 200*52.41 - 200*52.41 -> -200281 | AC12: =-22*164.11-50*164.13-50*164.18 -> -20025.92 | AD12: 0 | AE12: 0 | AF12: 0 | AG12: 0 | AH12: 0 | AI12: =SUM(C12:AH12) -> -158162.36 | AJ12: =SUM(AI11:AI12) -> 249691.57
B13: Rebecimento de proventos (-) | C13: 0 | D13: 0 | E13: 0 | G13: 0 | H13: 0 | I13: 0 | J13: 0 | K13: 0 | L13: 0 | M13: 0 | N13: 0 | O13: 0 | P13: 0 | Q13: 0 | R13: 0 | S13: 0 | T13: 0 | U13: 0 | V13: 0 | W13: 0 | X13: 0 | Y13: 0 | Z13: 0 | AA13: 0 | AB13: 0 | AC13: 0 | AD13: 0 | AE13: 0 | AF13: 0 | AG13: 0 | AH13: 0 | AI13: =SUM(C13:AH13) -> 0 | AJ13: =SUM(AI10:AI13) -> 3404663.2
B14: Valor final no mês | C14: =+(12810.76+21234.84)*0+(12846.89+21293.51)*0+(+21317.01+12861.07)*0+(21364.24+12889.33) -> 34253.57 | D14: =+152925.14*0+153342.8*0+153511.95*0+153850.98 -> 153850.98 | E14: =+((+32199.68+23410)+(-30192.43-39361.2-35766))*0+((+7194.69+25458)+(-30192.43-39361.2-35766))*0+((-21973+17201.39)+(-35000-30192-37480))*0+((+894-37480-35000-30192)+(+97372+27911-71287-3995))*0+((+26070-2623)+(+894-37480-35000-39159))*0+((+17753-2623)+(-39158-13288-37481+19405)+(+26500+15240))*0+((82846+12549)+(-39158-13288-37481+19405))*0+((+127655-23863)+(+9185-18158-34288-37481))*0+((-23863+70155)+(-39158))*0+((+62999-27643)+(-39158-27532))*0+((+600-5598)+(-18999)+(+13870+38700))*0+((+52566-58781)+(-18899)+(+13870+38700))*0+((+90992-44821)+(-18899))*0+((+90806)+(-24988-15000)+(+3543))*0+((+94226.4+178)+(-24988-15000))*0+(+49726+178)*0+((+29374)+(+2530))*0+(+31998+178)*0+(30657)*0+(19644.02)*0+(+22324+178)*0+(-29428.92+223.79)*0+((-65211+223)+(+4086+10132)+(+2731-22708))*0+(-55191+4310)+(+2731-22708) -> -70858 | F14: =+(+300+400)*148.12 -> 103684 | G14: =+115783*0+116105.09*0+116296.85*0+116489.59*0+116554.34 -> 116554.34 | H14: =+15636*0+15681.96 -> 15681.96 | I14: =+190535.15*0+191038.5*0+191204.15*0+191548.66*0+191652.08 -> 191652.08 | J14: =+235184.58*0+235843.38*0+236112.54*0+236634.81*0+236766.17 -> 236766.17 | K14: =+230295.13*0+230422.09*0+230676.23*0+231057.96*0+231057.96*0+231440.33*0+231695.59 -> 231695.59 | L14: =+89129.32*0+88375*0+97743*0+76306*0+(+76546+10000-18674.97)*0+68069.15*0+(67886+15000-9941.48)*0+72742.08*0+(72646+10000)*0+82802.92*0+83188*0+(+82912+5000)*0+(87668+12000)*0+98858 -> 98858 | M14: =+(339349+20734.59)*0+(+362041.84)+(18674.97+9941.18) -> 390657.99 | N14: =+750*38.87 -> 29152.5 | O14: =+121908.92*0+122155.68*0+122303.96*0+122514.18 -> 122514.18 | P14: =+231758.08*0+232258.6*0+232559.41*0+232860.62*0+232984.34 -> 232984.34 | Q14: =+63656.91*0+63669.16*0+63682.37*0+63978.03 -> 63978.03 | R14: =+(+1550-535-415-300+300)*121.7 -> 73020 | S14: =+(+70+70)*148.12 -> 20736.8 | T14: 0 | U14: =+(+11708+100)*66.92 -> 790191.36 | V14: =+(+1150+400)*87.39 -> 135454.5 | W14: 0 | X14: =+(+410+160)*131.95 -> 75211.5 | Y14: 0 | Z14: 0 | AA14: 0 | AB14: =+(+3300-400-900-2000)*52.4 -> 0 | AC14: =+(+695-122+374)*131.95 -> 124956.65 | AD14: =+(+450+200)*87.37 -> 56790.5 | AE14: 0 | AF14: =+2190*66.92 -> 146554.8 | AG14: 0 | AH14: 0 | AI14: =SUM(C14:AH14) -> 3374341.8 | AJ14: =AJ13-AI14 -> 30321.38
B15: Rentabilidade (ao mês) | C15: =IFERROR(IF(C14=0,(-C12/C10)-1,C16),"") -> 0.0072215404 | D15: =IFERROR(IF(D14=0,(-D12/D10)-1,D16),"") -> 0.0071606473 | E15: =IFERROR(IF(E14=0,(-E12/E10)-1,E16),"") -> 0 | F15: =IFERROR(IF(F14=0,(-F12/F10)-1,F16),"") -> 0.0030395725 | G15: =IFERROR(IF(G14=0,(-G12/G10)-1,G16),"") -> 0.0071650797 | H15: =IFERROR(IF(H14=0,(-H12/H10)-1,H16),"") -> 0.0071467656 | I15: =IFERROR(IF(I14=0,(-I12/I10)-1,I16),"") -> 0.0064312702 | J15: =IFERROR(IF(J14=0,(-J12/J10)-1,J16),"") -> 0.0072677434 | ... AI15: =IFERROR(IF(AI14=0,(-AI12/AI10)-1,AI16),"") -> -0.0089058383 | AJ15: =AI14*AI15 -> -30051.343
B16: Não mexer | C16: =IFERROR(IF(AND(C10<>0,C14=""),"",(C14/(C10+C11+C12+C13))-1),"") -> 0.0072215404 | D16: =IFERROR(IF(AND(D10<>0,D14=""),"",(D14/(D10+D11+D12+D13))-1),"") -> 0.0071606473 | E16: =IFERROR(IF(AND(E10<>0,E14=""),"",(E14/(E10+E11+E12+E13))-1),"") -> 0 | F16: =IFERROR(IF(AND(F10<>0,F14=""),"",(F14/(F10+F11+F12+F13))-1),"") -> 0.0030395725 | G16: =IFERROR(IF(AND(G10<>0,G14=""),"",(G14/(G10+G11+G12+G13))-1),"") -> 0.0071650797 | H16: =IFERROR(IF(AND(H10<>0,H14=""),"",(H14/(H10+H11+H12+H13))-1),"") -> 0.0071467656 | I16: =IFERROR(IF(AND(I10<>0,I14=""),"",(I14/(I10+I11+I12+I13))-1),"") -> 0.0064312702 | J16: =IFERROR(IF(AND(J10<>0,J14=""),"",(J14/(J10+J11+J12+J13))-1),"") -> 0.0072677434 | ... AI16: =IFERROR(IF(AND(AI10<>0,AI14=""),"",(AI14/(AI10+AI11+AI12+AI13))-1),"") -> -0.0089058383
B17: Ativo/PL | C17: =IFERROR(C14/$AI$14,"") -> 0.010151186 | D17: =IFERROR(D14/$AI$14,"") -> 0.045594367 | E17: =IFERROR(E14/$AI$14,"") -> -0.020999058 | F17: =IFERROR(F14/$AI$14,"") -> 0.030727177 | G17: =IFERROR(G14/$AI$14,"") -> 0.034541355 | H17: =IFERROR(H14/$AI$14,"") -> 0.004647413 | I17: =IFERROR(I14/$AI$14,"") -> 0.056796877 | J17: =IFERROR(J14/$AI$14,"") -> 0.070166622 | ... AI17: =IFERROR(AI14/$AI$14,"") -> 1 | AJ17: =AI14-AI10 -> 219370.19 | AK17: =AI14/AI10-1 -> 0.069531588
A18: 45717 | B18: Valor-base | C18: =IF(C22="","",C14) -> 34253.57 | D18: =IF(D22="","",D14) -> 153850.98 | E18: =IF(E22="","",E14) -> -70858 | F18: =IF(F22="","",F14) -> 103684 | G18: =IF(G22="","",G14) -> 116554.34 | H18: =IF(H22="","",H14) -> 15681.96 | I18: =IF(I22="","",I14) -> 191652.08 | J18: =IF(J22="","",J14) -> 236766.17 | ... AH18: =IF(AH22="","",AH14) -> 0 | AI18: =SUM(C18:AH18) -> 3374341.8
B19: Investimento (+) | C19: 0 | D19: 0 | E19: 0 | F19: 0 | G19: 0 | H19: 0 | I19: 0 | J19: 0 | K19: 0 | L19: 0 | M19: 0 | N19: 0 | O19: 0 | P19: 0 | Q19: 0 | R19: 0 | S19: 0 | T19: 0 | U19: 0 | V19: 0 | W19: 0 | X19: 0 | Y19: 0 | Z19: 0 | AA19: 0 | AB19: 0 | AC19: 0 | AD19: 0 | AE19: 0 | AF19: 0 | AG19: 0 | AH19: 0 | AI19: =SUM(C19:AH19) -> 0
B20: Resgate (-) | C20: 0 | D20: 0 | E20: 0 | F20: 0 | G20: 0 | H20: 0 | I20: 0 | J20: 0 | K20: 0 | L20: 0 | M20: 0 | N20: 0 | O20: 0 | P20: 0 | Q20: 0 | R20: 0 | S20: 0 | T20: 0 | U20: 0 | V20: 0 | W20: 0 | X20: 0 | Y20: 0 | Z20: 0 | AA20: 0 | AB20: 0 | AC20: 0 | AD20: 0 | AE20: 0 | AF20: 0 | AG20: 0 | AH20: 0 | AI20: =SUM(C20:AH20) -> 0 | AJ20: =SUM(AI19:AI20) -> 0
B21: Rebecimento de proventos (-) | C21: 0 | D21: 0 | E21: 0 | F21: 0 | G21: 0 | H21: 0 | I21: 0 | J21: 0 | K21: 0 | L21: 0 | M21: 0 | N21: 0 | O21: 0 | P21: 0 | Q21: 0 | R21: 0 | S21: 0 | T21: 0 | U21: 0 | V21: 0 | W21: 0 | X21: 0 | Y21: 0 | Z21: 0 | AA21: 0 | AB21: 0 | AC21: 0 | AD21: 0 | AE21: 0 | AF21: 0 | AG21: 0 | AH21: 0 | AI21: =SUM(C21:AH21) -> 0 | AJ21: =SUM(AI18:AI21) -> 3374341.8
B22: Valor final no mês | C22: 0 | D22: 0 | E22: 0 | F22: 0 | G22: 0 | H22: 0 | I22: 0 | J22: 0 | K22: 0 | L22: 0 | M22: 0 | N22: 0 | O22: 0 | P22: 0 | Q22: 0 | R22: 0 | S22: 0 | T22: 0 | U22: 0 | V22: 0 | W22: 0 | X22: 0 | Y22: 0 | Z22: 0 | AA22: 0 | AB22: 0 | AC22: 0 | AD22: 0 | AE22: 0 | AF22: 0 | AG22: 0 | AH22: 0 | AI22: =SUM(C22:AH22) -> 0 | AJ22: =AJ21-AI22 -> 3374341.8
B23: Rentabilidade (ao mês) | C23: =IFERROR(IF(C22=0,(-C20/C18)-1,C24),"") -> -1 | D23: =IFERROR(IF(D22=0,(-D20/D18)-1,D24),"") -> -1 | E23: =IFERROR(IF(E22=0,(-E20/E18)-1,E24),"") -> -1 | F23: =IFERROR(IF(F22=0,(-F20/F18)-1,F24),"") -> -1 | G23: =IFERROR(IF(G22=0,(-G20/G18)-1,G24),"") -> -1 | H23: =IFERROR(IF(H22=0,(-H20/H18)-1,H24),"") -> -1 | I23: =IFERROR(IF(I22=0,(-I20/I18)-1,I24),"") -> -1 | J23: =IFERROR(IF(J22=0,(-J20/J18)-1,J24),"") -> -1 | ... AI23: =IFERROR(IF(AI22=0,(-AI20/AI18)-1,AI24),"") -> -1 | AJ23: =AI22*AI23 -> 0
B24: Não mexer | C24: =IFERROR(IF(AND(C18<>0,C22=""),"",(C22/(C18+C19+C20+C21))-1),"") -> -1 | D24: =IFERROR(IF(AND(D18<>0,D22=""),"",(D22/(D18+D19+D20+D21))-1),"") -> -1 | E24: =IFERROR(IF(AND(E18<>0,E22=""),"",(E22/(E18+E19+E20+E21))-1),"") -> -1 | F24: =IFERROR(IF(AND(F18<>0,F22=""),"",(F22/(F18+F19+F20+F21))-1),"") -> -1 | G24: =IFERROR(IF(AND(G18<>0,G22=""),"",(G22/(G18+G19+G20+G21))-1),"") -> -1 | H24: =IFERROR(IF(AND(H18<>0,H22=""),"",(H22/(H18+H19+H20+H21))-1),"") -> -1 | I24: =IFERROR(IF(AND(I18<>0,I22=""),"",(I22/(I18+I19+I20+I21))-1),"") -> -1 | J24: =IFERROR(IF(AND(J18<>0,J22=""),"",(J22/(J18+J19+J20+J21))-1),"") -> -1 | ... AI24: =IFERROR(IF(AND(AI18<>0,AI22=""),"",(AI22/(AI18+AI19+AI20+AI21))-1),"") -> -1
B25: Ativo/PL | C25: =IFERROR(C22/$AI$22,"") | D25: =IFERROR(D22/$AI$22,"") | E25: =IFERROR(E22/$AI$22,"") | F25: =IFERROR(F22/$AI$22,"") | G25: =IFERROR(G22/$AI$22,"") | H25: =IFERROR(H22/$AI$22,"") | I25: =IFERROR(I22/$AI$22,"") | J25: =IFERROR(J22/$AI$22,"") | ... AI25: =IFERROR(AI22/$AI$22,"") | AJ25: =AI22-AI18 -> -3374341.8 | AK25: =AI22/AI18-1 -> -1
A26: 45748 | B26: Valor-base | C26: =IF(C30="","",C22) -> 0 | D26: =IF(D30="","",D22) -> 0 | E26: =IF(E30="","",E22) -> 0 | F26: =IF(F30="","",F22) -> 0 | G26: =IF(G30="","",G22) -> 0 | H26: =IF(H30="","",H22) -> 0 | I26: =IF(I30="","",I22) -> 0 | J26: =IF(J30="","",J22) -> 0 | ... AH26: =IF(AH30="","",AH22) -> 0 | AI26: =SUM(C26:AH26) -> 0
B27: Investimento (+) | C27: 0 | D27: 0 | E27: 0 | F27: 0 | G27: 0 | H27: 0 | I27: 0 | J27: 0 | K27: 0 | L27: 0 | M27: 0 | N27: 0 | O27: 0 | P27: 0 | Q27: 0 | R27: 0 | S27: 0 | T27: 0 | U27: 0 | V27: 0 | W27: 0 | X27: 0 | Y27: 0 | Z27: 0 | AA27: 0 | AB27: 0 | AC27: 0 | AD27: 0 | AE27: 0 | AF27: 0 | AG27: 0 | AH27: 0 | AI27: =SUM(C27:AH27) -> 0
B28: Resgate (-) | C28: 0 | D28: 0 | E28: 0 | F28: 0 | G28: 0 | H28: 0 | I28: 0 | J28: 0 | K28: 0 | L28: 0 | M28: 0 | N28: 0 | O28: 0 | P28: 0 | Q28: 0 | R28: 0 | S28: 0 | T28: 0 | U28: 0 | V28: 0 | W28: 0 | X28: 0 | Y28: 0 | Z28: 0 | AA28: 0 | AB28: 0 | AC28: 0 | AD28: 0 | AE28: 0 | AF28: 0 | AG28: 0 | AH28: 0 | AI28: =SUM(C28:AH28) -> 0
B29: Rebecimento de proventos (-) | C29: 0 | D29: 0 | E29: 0 | F29: 0 | G29: 0 | H29: 0 | I29: 0 | J29: 0 | K29: 0 | L29: 0 | M29: 0 | N29: 0 | O29: 0 | P29: 0 | Q29: 0 | R29: 0 | S29: 0 | T29: 0 | U29: 0 | V29: 0 | W29: 0 | X29: 0 | Y29: 0 | Z29: 0 | AA29: 0 | AB29: 0 | AC29: 0 | AD29: 0 | AE29: 0 | AF29: 0 | AG29: 0 | AH29: 0 | AI29: =SUM(C29:AH29) -> 0 | AJ29: =SUM(AI26:AI29) -> 0
B30: Valor final no mês | C30: 0 | D30: 0 | E30: 0 | F30: 0 | G30: 0 | H30: 0 | I30: 0 | J30: 0 | K30: 0 | L30: 0 | M30: 0 | N30: 0 | O30: 0 | P30: 0 | Q30: 0 | R30: 0 | S30: 0 | T30: 0 | U30: 0 | V30: 0 | W30: 0 | X30: 0 | Y30: 0 | Z30: 0 | AA30: 0 | AB30: 0 | AC30: 0 | AD30: 0 | AE30: 0 | AF30: 0 | AG30: 0 | AH30: 0 | AI30: =SUM(C30:AH30) -> 0 | AJ30: =AJ29-AI30 -> 0
B31: Rentabilidade (ao mês) | C31: =IFERROR(IF(C30=0,(-C28/C26)-1,C32),"") | D31: =IFERROR(IF(D30=0,(-D28/D26)-1,D32),"") | E31: =IFERROR(IF(E30=0,(-E28/E26)-1,E32),"") | F31: =IFERROR(IF(F30=0,(-F28/F26)-1,F32),"") | G31: =IFERROR(IF(G30=0,(-G28/G26)-1,G32),"") | H31: =IFERROR(IF(H30=0,(-H28/H26)-1,H32),"") | I31: =IFERROR(IF(I30=0,(-I28/I26)-1,I32),"") | J31: =IFERROR(IF(J30=0,(-J28/J26)-1,J32),"") | ... AI31: =IFERROR(IF(AI30=0,(-AI28/AI26)-1,AI32),"") | AJ31: =AI30*AI31 -> 0
B32: Não mexer | C32: =IFERROR(IF(AND(C26<>0,C30=""),"",(C30/(C26+C27+C28+C29))-1),"") | D32: =IFERROR(IF(AND(D26<>0,D30=""),"",(D30/(D26+D27+D28+D29))-1),"") | E32: =IFERROR(IF(AND(E26<>0,E30=""),"",(E30/(E26+E27+E28+E29))-1),"") | F32: =IFERROR(IF(AND(F26<>0,F30=""),"",(F30/(F26+F27+F28+F29))-1),"") | G32: =IFERROR(IF(AND(G26<>0,G30=""),"",(G30/(G26+G27+G28+G29))-1),"") | H32: =IFERROR(IF(AND(H26<>0,H30=""),"",(H30/(H26+H27+H28+H29))-1),"") | I32: =IFERROR(IF(AND(I26<>0,I30=""),"",(I30/(I26+I27+I28+I29))-1),"") | J32: =IFERROR(IF(AND(J26<>0,J30=""),"",(J30/(J26+J27+J28+J29))-1),"") | ... AI32: =IFERROR(IF(AND(AI26<>0,AI30=""),"",(AI30/(AI26+AI27+AI28+AI29))-1),"")
B33: Ativo/PL | C33: =IFERROR(C30/$AI$30,"") | D33: =IFERROR(D30/$AI$30,"") | E33: =IFERROR(E30/$AI$30,"") | F33: =IFERROR(F30/$AI$30,"") | G33: =IFERROR(G30/$AI$30,"") | H33: =IFERROR(H30/$AI$30,"") | I33: =IFERROR(I30/$AI$30,"") | J33: =IFERROR(J30/$AI$30,"") | ... AI33: =IFERROR(AI30/$AI$30,"") | AJ33: =AI30-AI26 -> 0 | AK33: =AI30/AI26-1 -> #DIV/0!
A34: 45778 | B34: Valor-base | C34: =IF(C38="","",C30) -> 0 | D34: =IF(D38="","",D30) -> 0 | E34: =IF(E38="","",E30) -> 0 | F34: =IF(F38="","",F30) -> 0 | G34: =IF(G38="","",G30) -> 0 | H34: =IF(H38="","",H30) -> 0 | I34: =IF(I38="","",I30) -> 0 | J34: =IF(J38="","",J30) -> 0 | ... AH34: =IF(AH38="","",AH30) -> 0 | AI34: =SUM(C34:AH34) -> 0
B35: Investimento (+) | C35: 0 | D35: 0 | E35: 0 | F35: 0 | G35: 0 | H35: 0 | I35: 0 | J35: 0 | K35: 0 | L35: 0 | M35: 0 | N35: 0 | O35: 0 | P35: 0 | Q35: 0 | R35: 0 | S35: 0 | T35: 0 | U35: 0 | V35: 0 | W35: 0 | X35: 0 | Y35: 0 | Z35: 0 | AA35: 0 | AB35: 0 | AC35: 0 | AD35: 0 | AE35: 0 | AF35: 0 | AG35: 0 | AH35: 0 | AI35: =SUM(C35:AH35) -> 0
B36: Resgate (-) | C36: 0 | D36: 0 | E36: 0 | F36: 0 | G36: 0 | H36: 0 | I36: 0 | J36: 0 | K36: 0 | L36: 0 | M36: 0 | N36: 0 | O36: 0 | P36: 0 | Q36: 0 | R36: 0 | S36: 0 | T36: 0 | U36: 0 | V36: 0 | W36: 0 | X36: 0 | Y36: 0 | Z36: 0 | AA36: 0 | AB36: 0 | AC36: 0 | AD36: 0 | AE36: 0 | AF36: 0 | AG36: 0 | AH36: 0 | AI36: =SUM(C36:AH36) -> 0
B37: Rebecimento de proventos (-) | C37: 0 | D37: 0 | E37: 0 | F37: 0 | G37: 0 | H37: 0 | I37: 0 | J37: 0 | K37: 0 | L37: 0 | M37: 0 | N37: 0 | O37: 0 | P37: 0 | Q37: 0 | R37: 0 | S37: 0 | T37: 0 | U37: 0 | V37: 0 | W37: 0 | X37: 0 | Y37: 0 | Z37: 0 | AA37: 0 | AB37: 0 | AC37: 0 | AD37: 0 | AE37: 0 | AF37: 0 | AG37: 0 | AH37: 0 | AI37: =SUM(C37:AH37) -> 0 | AJ37: =SUM(AI34:AI37) -> 0
B38: Valor final no mês | C38: 0 | D38: 0 | E38: 0 | F38: 0 | G38: 0 | H38: 0 | I38: 0 | J38: 0 | K38: 0 | L38: 0 | M38: 0 | N38: 0 | O38: 0 | P38: 0 | Q38: 0 | R38: 0 | S38: 0 | T38: 0 | U38: 0 | V38: 0 | W38: 0 | X38: 0 | Y38: 0 | Z38: 0 | AA38: 0 | AB38: 0 | AC38: 0 | AD38: 0 | AE38: 0 | AF38: 0 | AG38: 0 | AH38: 0 | AI38: =SUM(C38:AH38) -> 0 | AJ38: =AJ37-AI38 -> 0
B39: Rentabilidade (ao mês) | C39: =IFERROR(IF(C38=0,(-C36/C34)-1,C40),"") | D39: =IFERROR(IF(D38=0,(-D36/D34)-1,D40),"") | E39: =IFERROR(IF(E38=0,(-E36/E34)-1,E40),"") | F39: =IFERROR(IF(F38=0,(-F36/F35)-1,F40),"") | G39: =IFERROR(IF(G38=0,(-G36/G34)-1,G40),"") | H39: =IFERROR(IF(H38=0,(-H36/H34)-1,H40),"") | I39: =IFERROR(IF(I38=0,(-I36/I34)-1,I40),"") | J39: =IFERROR(IF(J38=0,(-J36/J34)-1,J40),"") | K39: =IFERROR(IF(K38=0,(-K36/K34)-1,K40),"") | L39: =IFERROR(IF(L38=0,(-L36/L34)-1,L40),"") | M39: =IFERROR(IF(M38=0,(-M36/M34)-1,M40),"") | N39: =IFERROR(IF(N38=0,(-N36/N34)-1,N40),"") | ... AF39: =IFERROR(IF(AF38=0,(-AF36/AF34)-1,AF40),"") | AG39: =IFERROR(IF(AG38=0,(-AG36/AG35)-1,AG40),"") | AH39: =IFERROR(IF(AH38=0,(-AH36/AH34)-1,AH40),"") | AI39: =IFERROR(IF(AI38=0,(-AI36/AI34)-1,AI40),"") | AJ39: =AI38*AI39 -> 0
B40: Não mexer | C40: =IFERROR(IF(AND(C34<>0,C38=""),"",(C38/(C34+C35+C36+C37))-1),"") | D40: =IFERROR(IF(AND(D34<>0,D38=""),"",(D38/(D34+D35+D36+D37))-1),"") | E40: =IFERROR(IF(AND(E34<>0,E38=""),"",(E38/(E34+E35+E36+E37))-1),"") | F40: =IFERROR(IF(AND(F34<>0,F38=""),"",(F38/(F34+F35+F36+F37))-1),"") | G40: =IFERROR(IF(AND(G34<>0,G38=""),"",(G38/(G34+G35+G36+G37))-1),"") | H40: =IFERROR(IF(AND(H34<>0,H38=""),"",(H38/(H34+H35+H36+H37))-1),"") | I40: =IFERROR(IF(AND(I34<>0,I38=""),"",(I38/(I34+I35+I36+I37))-1),"") | J40: =IFERROR(IF(AND(J34<>0,J38=""),"",(J38/(J34+J35+J36+J37))-1),"") | ... AI40: =IFERROR(IF(AND(AI34<>0,AI38=""),"",(AI38/(AI34+AI35+AI36+AI37))-1),"")
...

Sheet % de Alocação da Carteira 02_25
B2: ANALISE % de Alocação da Carteira "Nasser Family"p/ Produto Financeiro (02/2024) | M2: ALOCAÇÃO % COMPACTA
E3: =+SUM(E4:E14) -> 1
B4: CAIXA | D4: =+'Planilha de Rentabilidade'!E14 -> -70858 | E4: =D4/$E$15 -> -0.020999058 | L4: IPCA + | M4: =SUM(D5:D7) -> 419476.55 | N4: =M4/$M$15 -> 0.12431359
B5: TESOURO IPCA+2035 | D5: =+'Planilha de Rentabilidade'!Q14 -> 63978.03 | E5: =D5/$E$15 -> 0.018960151 | M5: 0 | N5: =M5/$M$15 -> 0
B6: DEBENTURE | D6: =+'Planilha de Rentabilidade'!P14 -> 232984.34 | E6: =D6/$E$15 -> 0.069045862 | M6: 0 | N6: =M6/$M$15 -> 0
B7: CRI CRA | D7: ='Planilha de Rentabilidade'!O14 -> 122514.18 | E7: =D7/$E$15 -> 0.036307578 | L7: LCA | M7: =+D11 -> 0 | N7: =M7/$M$15 -> 0
B8: TESOURO SELIC + LFTS11 | D8: =+'Planilha de Rentabilidade'!C14+'Planilha de Rentabilidade'!D14+'Planilha de Rentabilidade'!F14+'Planilha de Rentabilidade'!S14 -> 312525.35 | E8: =D8/$E$15 -> 0.092618165 | L8: RENDA FIXA | M8: =D8+D12+D13 -> 1104875.5 | N8: =M8/$M$15 -> 0.32743437
B9: MOEDAS | D9: ='Planilha de Rentabilidade'!L14 -> 98858 | E9: =D9/$E$15 -> 0.029296972 | L9: GOLD + $$ | M9: =+D10 -> 390657.99 | N9: =M9/$M$15 -> 0.11577309
B10: GOLD+$ | D10: ='Planilha de Rentabilidade'!M14 -> 390657.99 | E10: =D10/$E$15 -> 0.11577309 | L10: MOEDAS | M10: =D9 -> 98858 | N10: =M10/$M$15 -> 0.029296972
B11: LCA | D11: =0 -> 0 | E11: =D11/$E$15 -> 0 | N11: =M11/$M$15 -> 0
B12: FUNDO DI | D12: ='Planilha de Rentabilidade'!G14+'Planilha de Rentabilidade'!I14+'Planilha de Rentabilidade'!J14 -> 544972.59 | E12: =D12/$E$15 -> 0.16150486 | L12: CAIXA | M12: =+D4 -> -70858 | N12: =M12/$M$15 -> -0.020999058
B13: CDB DI | D13: =+'Planilha de Rentabilidade'!H14+'Planilha de Rentabilidade'!K14 -> 247377.55 | E13: =D13/$E$15 -> 0.073311348 | N13: =M13/$M$15 -> 0
B14: RENDA VARIAVEL | D14: =B33 -> 1431331.8 | E14: =D14/$E$15 -> 0.42418103 | L14: R.V. | M14: =D14 -> 1431331.8 | N14: =M14/$M$15 -> 0.42418103
C15: Total da Carteira Nasser Family ==> | E15: =SUM(D4:D14) -> 3374341.8 | M15: =SUM(M4:M14) -> 3374341.8 | N15: =SUM(N4:N14) -> 1
B18: ANALISE % Alocação da Carteira "Nasser Family" RENDA VARIAVEL(02/2024)
C19: % Renda Variavel Alocadas por Setor
B20: ='Planilha de Rentabilidade'!Z14+'Planilha de Rentabilidade'!AA14+'Planilha de Rentabilidade'!W14 -> 0 | C20: =B20/$B$33 -> 0 | D20: IRON ORE
B21: =0 -> 0 | C21: =B21/$B$33 -> 0 | D21: SOJA
B22: ='Planilha de Rentabilidade'!U14+'Planilha de Rentabilidade'!AF14 -> 936746.16 | C22: =B22/$B$33 -> 0.65445772 | D22: Electric Vehicle
B23: ='Planilha de Rentabilidade'!AD14+'Planilha de Rentabilidade'!V14 -> 192245 | C23: =B23/$B$33 -> 0.13431197 | D23: MELI
B24: ='Planilha de Rentabilidade'!AH14 -> 0 | C24: =B24/$B$33 -> 0 | D24: LITHIUM
B25: 0 | C25: =B25/$B$33 -> 0 | D25: ENERGIA
B26: 0 | C26: =B26/$B$33 -> 0 | D26: CELULOSE
B27: 0 | C27: =B27/$B$33 -> 0 | D27: Saude
B28: =+'Planilha de Rentabilidade'!R14 -> 73020 | C28: =B28/$B$33 -> 0.051015425 | D28: AURA
B29: =+'Planilha de Rentabilidade'!X14+'Planilha de Rentabilidade'!AC14 -> 200168.15 | C29: =B29/$B$33 -> 0.13984748 | D29: AMD
B30: ='Planilha de Rentabilidade'!AB79+'Planilha de Rentabilidade'!AC79 -> 0 | C30: =B30/$B$33 -> 0 | D30: APPLE
B31: =+'Planilha de Rentabilidade'!N14 -> 29152.5 | C31: =B31/$B$33 -> 0.020367395 | D31: INTEL
B32: =+'Planilha de Rentabilidade'!AB14 -> 0 | C32: =B32/$B$33 -> 0 | D32: WEGE
B33: =SUM(B20:B32) -> 1431331.8 | C33: =B33/$B$33 -> 1

Sheet Alocação da Carteira 04_25
B2: ANALISE % de Alocação da Carteira "Nasser Family"p/ Produto Financeiro (04/2024) | M2: ALOCAÇÃO % COMPACTA
E3: =+SUM(E4:E14) -> #DIV/0!
B4: CAIXA | D4: =+'Planilha de Rentabilidade'!E30 -> 0 | E4: =D4/$E$15 -> #DIV/0! | L4: IPCA + | M4: =SUM(D5:D7) -> 0 | N4: =M4/$M$15 -> #DIV/0!
B5: TESOURO IPCA+2029 | D5: =+'Planilha de Rentabilidade'!Q30 -> 0 | E5: =D5/$E$15 -> #DIV/0! | M5: 0 | N5: =M5/$M$15 -> #DIV/0!
B6: DEBENTURE IPCA+7,60% | D6: =+'Planilha de Rentabilidade'!P30 -> 0 | E6: =D6/$E$15 -> #DIV/0! | M6: 0 | N6: =M6/$M$15 -> #DIV/0!
B7: CRI CRA | D7: 0 | E7: =D7/$E$15 -> #DIV/0! | L7: LCA | M7: =+D11 -> 0 | N7: =M7/$M$15 -> #DIV/0!
B8: TESOURO SELIC + LFTS11 | D8: =+'Planilha de Rentabilidade'!C30+'Planilha de Rentabilidade'!D30+'Planilha de Rentabilidade'!F30 -> 0 | E8: =D8/$E$15 -> #DIV/0! | L8: RENDA FIXA | M8: =D8+D12+D13 -> 0 | N8: =M8/$M$15 -> #DIV/0!
B9: MOEDAS | D9: ='Planilha de Rentabilidade'!L30 -> 0 | E9: =D9/$E$15 -> #DIV/0! | L9: $$ | M9: =+D10+D9 -> 0 | N9: =M9/$M$15 -> #DIV/0!
B10: GOLD + $$$ | D10: ='Planilha de Rentabilidade'!M30 -> 0 | E10: =D10/$E$15 -> #DIV/0! | N10: =M10/$M$15 -> #DIV/0!
B11: LCA | D11: =+0 -> 0 | E11: =D11/$E$15 -> #DIV/0! | N11: =M11/$M$15 -> #DIV/0!
B12: FUNDO DI | D12: =+'Planilha de Rentabilidade'!G30+'Planilha de Rentabilidade'!I30 -> 0 | E12: =D12/$E$15 -> #DIV/0! | L12: CAIXA | M12: =+D4 -> 0 | N12: =M12/$M$15 -> #DIV/0!
B13: CDB DI | D13: =+'Planilha de Rentabilidade'!H30+'Planilha de Rentabilidade'!J30+'Planilha de Rentabilidade'!K30+'Planilha de Rentabilidade'!S30+'Planilha de Rentabilidade'!V30 -> 0 | E13: =D13/$E$15 -> #DIV/0! | N13: =M13/$M$15 -> #DIV/0!
B14: RENDA VARIAVEL | D14: =B35 -> 0 | E14: =D14/$E$15 -> #DIV/0! | L14: R.V. | M14: =D14 -> 0 | N14: =M14/$M$15 -> #DIV/0!
E15: =SUM(D4:D14) -> 0 | M15: =SUM(M4:M14) -> 0 | N15: =SUM(N4:N14) -> #DIV/0!
B18: ANALISE % Alocação da Carteira "Nasser Family" RENDA VARIAVEL(04/2024)
C19: % Renda Variavel Alocadas por Setor
B20: =+'Planilha de Rentabilidade'!Z30 -> 0 | C20: =B20/$B$35 -> #DIV/0! | D20: IRON ORE
B21: =+'Planilha de Rentabilidade'!O30 -> 0 | C21: =B21/$B$35 -> #DIV/0! | D21: SOJA
B22: =+'Planilha de Rentabilidade'!U30+'Planilha de Rentabilidade'!AB30 -> 0 | C22: =B22/$B$35 -> #DIV/0! | D22: Electric Vehicle
B23: 0 | C23: =B23/$B$35 -> #DIV/0! | D23: Tec.NVIDIA
B24: 0 | C24: =B24/$B$35 -> #DIV/0! | D24: LITHIUM
B25: 0 | C25: =B25/$B$35 -> #DIV/0! | D25: industria BEBIDAS
B26: 0 | C26: =B26/$B$35 -> #DIV/0! | D26: CELULOSE
B27: =+'Planilha de Rentabilidade'!AA30+'Planilha de Rentabilidade'!AC30 -> 0 | C27: =B27/$B$35 -> #DIV/0! | D27: Saude
B28: 0 | C28: =B28/$B$35 -> #DIV/0! | D28: Comodites_GOLD
B29: =+'Planilha de Rentabilidade'!X30+'Planilha de Rentabilidade'!Y30 -> 0 | C29: =B29/$B$35 -> #DIV/0! | D29: ASML
B30: =+'Planilha de Rentabilidade'!T30 -> 0 | C30: =B30/$B$35 -> #DIV/0! | D30: APPLE
B31: =+'Planilha de Rentabilidade'!N30+'Planilha de Rentabilidade'!AH30 -> 0 | C31: =B31/$B$35 -> #DIV/0! | D31: INTEL
B32: 0 | C32: 0 | D32: CARROCERIAS ONIBUS
C33: =SUM(C20:C32) -> #DIV/0!
B35: =SUM(B20:B34) -> 0 | C35: =B35/$B$35 -> #DIV/0!

Sheet % de Alocação da Carteira 03_25
B2: ANALISE % de Alocação da Carteira "Nasser Family"p/ Produto Financeiro (03/2024) | M2: ALOCAÇÃO % COMPACTA
E3: =+SUM(E4:E14) -> #DIV/0!
B4: CAIXA | D4: =+'Planilha de Rentabilidade'!E22 -> 0 | E4: =D4/$E$15 -> #DIV/0! | L4: IPCA + | M4: =SUM(D5:D7) -> 0 | N4: =M4/$M$15 -> #DIV/0!
B5: TESOURO IPCA+2029 | D5: =+'Planilha de Rentabilidade'!Q22 -> 0 | E5: =D5/$E$15 -> #DIV/0! | M5: 0 | N5: =M5/$M$15 -> #DIV/0!
B6: DEBENTURE IPCA+7,60% | D6: =+'Planilha de Rentabilidade'!P22 -> 0 | E6: =D6/$E$15 -> #DIV/0! | M6: 0 | N6: =M6/$M$15 -> #DIV/0!
B7: CRI CRA | D7: 0 | E7: =D7/$E$15 -> #DIV/0! | L7: LCA | M7: =+D11 -> 0 | N7: =M7/$M$15 -> #DIV/0!
B8: TESOURO SELIC + LFTS11 | D8: ='Planilha de Rentabilidade'!C22+'Planilha de Rentabilidade'!D22+'Planilha de Rentabilidade'!F22 -> 0 | E8: =D8/$E$15 -> #DIV/0! | L8: RENDA FIXA | M8: =D8+D12+D13 -> 0 | N8: =M8/$M$15 -> #DIV/0!
B9: MOEDAS | D9: ='Planilha de Rentabilidade'!L22 -> 0 | E9: =D9/$E$15 -> #DIV/0! | L9: GOLD + $$ | M9: =+D10 -> 0 | N9: =M9/$M$15 -> #DIV/0!
B10: GOLD + $$$ | D10: ='Planilha de Rentabilidade'!M22 -> 0 | E10: =D10/$E$15 -> #DIV/0! | L10: MOEDAS | M10: =D9 -> 0 | N10: =M10/$M$15 -> #DIV/0!
B11: LCA | D11: 0 | E11: =D11/$E$15 -> #DIV/0! | N11: =M11/$M$15 -> #DIV/0!
B12: FUNDO DI | D12: ='Planilha de Rentabilidade'!I22+'Planilha de Rentabilidade'!G22 -> 0 | E12: =D12/$E$15 -> #DIV/0! | L12: CAIXA | M12: =+D4 -> 0 | N12: =M12/$M$15 -> #DIV/0!
B13: CDB DI | D13: =+'Planilha de Rentabilidade'!H22+'Planilha de Rentabilidade'!K22+'Planilha de Rentabilidade'!S22+'Planilha de Rentabilidade'!V22+'Planilha de Rentabilidade'!J22 -> 0 | E13: =D13/$E$15 -> #DIV/0! | N13: =M13/$M$15 -> #DIV/0!
B14: RENDA VARIAVEL | D14: =B35 -> 0 | E14: =D14/$E$15 -> #DIV/0! | L14: R.V. | M14: =D14 -> 0 | N14: =M14/$M$15 -> #DIV/0!
C15: Total da Carteira Nasser Family ==> | E15: =SUM(D4:D14) -> 0 | M15: =SUM(M4:M14) -> 0 | N15: =SUM(N4:N14) -> #DIV/0!
B18: ANALISE % Alocação da Carteira "Nasser Family" RENDA VARIAVEL(03/2024)
C19: % Renda Variavel Alocadas por Setor
B20: ='Planilha de Rentabilidade'!Z22+'Planilha de Rentabilidade'!W22 -> 0 | C20: =B20/$B$35 -> #DIV/0! | D20: Comodites_IRON ORE
B21: =+'Planilha de Rentabilidade'!O22 -> 0 | C21: =B21/$B$35 -> #DIV/0! | D21: SOJA
B22: ='Planilha de Rentabilidade'!AB22+'Planilha de Rentabilidade'!U22 -> 0 | C22: =B22/$B$35 -> #DIV/0! | D22: Electric Vehicle
B23: 0 | C23: =B23/$B$35 -> #DIV/0! | D23: Tec.NVIDIA
B24: 0 | C24: =B24/$B$35 -> #DIV/0! | D24: LITHIUM
B25: 0 | C25: =B25/$B$35 -> #DIV/0! | D25: industria BEBIDAS
B26: ='Planilha de Rentabilidade'!AH22 -> 0 | C26: =B26/$B$35 -> #DIV/0! | D26: CELULOSE
B27: ='Planilha de Rentabilidade'!AA22+'Planilha de Rentabilidade'!AC22 -> 0 | C27: =B27/$B$35 -> #DIV/0! | D27: Saude
B28: 0 | C28: =B28/$B$35 -> #DIV/0! | D28: Comodites_GOLD
B29: =+'Planilha de Rentabilidade'!Y22+'Planilha de Rentabilidade'!X22 -> 0 | C29: =B29/$B$35 -> #DIV/0! | D29: ASML
B30: 0 | C30: =B30/$B$35 -> #DIV/0! | D30: APPLE
B31: =+'Planilha de Rentabilidade'!N22 -> 0 | C31: =B31/$B$35 -> #DIV/0! | D31: INTEL
B32: 0 | C32: =B32/$B$35 -> #DIV/0! | D32: CARROCERIAS ONIBUS
C33: =SUM(C20:C32) -> #DIV/0!
B35: =SUM(B20:B34) -> 0 | C35: =B35/$B$35 -> #DIV/0!

Sheet % de Alocação da Carteira 05_25
B2: ANALISE % de Alocação da Carteira "Nasser Family"p/ Produto Financeiro (05/2023) | M2: ALOCAÇÃO % COMPACTA
E3: =SUM(E4:E14) -> #ERROR!
B4: CAIXA | D4: ='Planilha de Rentabilidade'!E38 -> 0 | E4: =D4/$D$15 -> #ERROR! | L4: IPCA + | M4: =SUM(D5:D7) -> 0 | N4: =M4/$M$15 -> #ERROR!
B5: TESOURO IPCA+2029 | D5: ='Planilha de Rentabilidade'!Q38 -> 0 | E5: =D5/$D$15 -> #ERROR! | N5: =M5/$M$15 -> #ERROR!
B6: DEBENTURE IPCA+7,60% | D6: ='Planilha de Rentabilidade'!P38 -> 0 | E6: =D6/$D$15 -> #ERROR! | M6: 0 | N6: =M6/$M$15 -> #ERROR!
B7: CRI CRA | D7: 0 | E7: =D7/$D$15 -> #ERROR! | L7: LCA | N7: =M7/$M$15 -> #ERROR!
B8: TESOURO SELIC + LFTS11 | D8: ='Planilha de Rentabilidade'!C38+'Planilha de Rentabilidade'!D38+'Planilha de Rentabilidade'!F38 -> 0 | E8: =D8/$D$15 -> #ERROR! | L8: RENDA FIXA | M8: =SUM(D8,D12,D13) -> 0 | N8: =M8/$M$15 -> #ERROR!
B9: MOEDAS | D9: ='Planilha de Rentabilidade'!L38 -> 0 | E9: =D9/$D$15 -> #ERROR! | L9: $$ | M9: =SUM(D9+D10) -> 0 | N9: =M9/$M$15 -> #ERROR!
B10: GOLD + $$$ | D10: ='Planilha de Rentabilidade'!M38 -> 0 | E10: =D10/$D$15 -> #ERROR! | N10: =M10/$M$15 -> #ERROR!
B11: LCA | D11: 0 | E11: =D11/$D$15 -> #ERROR! | N11: =M11/$M$15 -> #ERROR!
B12: FUNDO DI | D12: ='Planilha de Rentabilidade'!G38+'Planilha de Rentabilidade'!I38 -> 0 | E12: =D12/$D$15 -> #ERROR! | L12: CAIXA | M12: =D4 -> 0 | N12: =M12/$M$15 -> #ERROR!
B13: CDB DI | D13: ='Planilha de Rentabilidade'!H38+'Planilha de Rentabilidade'!J38+'Planilha de Rentabilidade'!K38+'Planilha de Rentabilidade'!S38+'Planilha de Rentabilidade'!V38 -> 0 | E13: =D13/$D$15 -> #ERROR! | N13: =M13/$M$15 -> #ERROR!
B14: RENDA VARIAVEL | D14: =B33 -> #ERROR! | E14: =D14/$D$15 -> #ERROR! | L14: Renda Variavel | M14: =D14 -> #ERROR! | N14: =M14/$M$15 -> #ERROR!
B15: Total da Carteira Nasser Family ==> | D15: =SUM(D4:D14) -> #ERROR! | E15: =SUM(E4:E14) -> #ERROR! | M15: =SUM(M4:M14) -> #ERROR! | N15: =SUM(N4:N14) -> #ERROR!
B18: ANALISE % Alocação da Carteira "Nasser Family" RENDA VARIAVEL(05/2023)
C19: % Renda Variavel Alocadas por Setor
B20: ='Planilha de Rentabilidade'!Z38 -> 0 | C20: =B20/$B$33 -> #ERROR! | D20: IRON ORE
B21: ='Planilha de Rentabilidade'!O38 -> 0 | C21: =B21/$B$33 -> #ERROR! | D21: SOJA
A22: CC | B22: ='Planilha de Rentabilidade'!U38+'Planilha de Rentabilidade'!AB38 -> 0 | C22: =B22/$B$33 -> #ERROR! | D22: Electric Vehicle
A23: FN | B23: =+'Planilha de Rentabilidade'!AG38 -> 0 | C23: =B23/$B$33 -> #ERROR! | D23: Tec.NVIDIA
A24: CM | B24: =+ -> #ERROR! | C24: =B24/$B$33 -> #ERROR! | D24: LITHIUM
A25: SD | B25: =+'Planilha de Rentabilidade'!AE38 -> 0 | C25: =B25/$B$33 -> #ERROR! | D25: FINANCEIRO
A26: GD | B26: 0 | C26: =B26/$B$33 -> #ERROR! | D26: CELULOSE
A27: EN | B27: ='Planilha de Rentabilidade'!AA38+'Planilha de Rentabilidade'!AC38 -> 0 | C27: =B27/$B$33 -> #ERROR! | D27: Saude
A28: VR | B28: 0 | C28: =B28/$B$33 -> #ERROR! | D28: Comodites_GOLD
A29: TC | B29: ='Planilha de Rentabilidade'!Y38+'Planilha de Rentabilidade'!X38 -> 0 | C29: =B29/$B$33 -> #ERROR! | D29: ASML
A30: SN | B30: ='Planilha de Rentabilidade'!T38 -> 0 | C30: =B30/$B$33 -> #ERROR! | D30: APPLE
B31: ='Planilha de Rentabilidade'!AH38+'Planilha de Rentabilidade'!N38 -> 0 | C31: =B31/$B$33 -> #ERROR! | D31: INTEL
B32: 0 | C32: =B32/$B$33 -> #ERROR! | D32: CARROCERIAS ONIBUS
B33: =SUM(B20:B32) -> #ERROR! | C33: =B33/$B$33 -> #ERROR!

Sheet % de Alocação da Carteira 06_25
B2: ANALISE % de Alocação da Carteira "Nasser Family"p/ Produto Financeiro (06/2023) | M2: ALOCAÇÃO % COMPACTA
E3: =+SUM(E4:E14) -> #DIV/0!
B4: CAIXA | D4: =+'Planilha de Rentabilidade'!E46 -> 0 | E4: =D4/$E$15 -> #DIV/0! | L4: IPCA + | M4: =+D5+D6 -> 0 | N4: =M4/$M$15 -> #DIV/0!
B5: TESOURO IPCA+2029 | D5: =+'Planilha de Rentabilidade'!Q46 -> 0 | E5: =D5/$E$15 -> #DIV/0! | N5: =M5/$M$15 -> #DIV/0!
B6: DEBENTURE IPCA+7,60% | D6: =+'Planilha de Rentabilidade'!P46 -> 0 | E6: =D6/$E$15 -> #DIV/0! | N6: =M6/$M$15 -> #DIV/0!
B7: CRI CRA | D7: 0 | E7: =D7/$E$15 -> #DIV/0! | L7: LCA | M7: 0 | N7: =M7/$M$15 -> #DIV/0!
B8: TESOURO SELIC + LFTS11 | D8: =+'Planilha de Rentabilidade'!C46+'Planilha de Rentabilidade'!D46+'Planilha de Rentabilidade'!F46 -> 0 | E8: =D8/$E$15 -> #DIV/0! | L8: RENDA FIXA | M8: =+D8+D12+D13 -> 0 | N8: =M8/$M$15 -> #DIV/0!
B9: MOEDAS | D9: =+'Planilha de Rentabilidade'!L46 -> 0 | E9: =D9/$E$15 -> #DIV/0! | L9: $$ | M9: =+D9+D10 -> 0 | N9: =M9/$M$15 -> #DIV/0!
B10: GOLD + $$$ | D10: =+'Planilha de Rentabilidade'!M46 -> 0 | E10: =D10/$E$15 -> #DIV/0! | M10: 0 | N10: =M10/$M$15 -> #DIV/0!
B11: LCA | D11: 0 | E11: =D11/$E$15 -> #DIV/0! | N11: =M11/$M$15 -> #DIV/0!
B12: FUNDO DI | D12: =+'Planilha de Rentabilidade'!G46+'Planilha de Rentabilidade'!I46 -> 0 | E12: =D12/$E$15 -> #DIV/0! | L12: CAIXA | M12: =+D4 -> 0 | N12: =M12/$M$15 -> #DIV/0!
B13: CDB DI | D13: =+'Planilha de Rentabilidade'!H46+'Planilha de Rentabilidade'!J46+'Planilha de Rentabilidade'!K46+'Planilha de Rentabilidade'!S46+'Planilha de Rentabilidade'!V46 -> 0 | E13: =D13/$E$15 -> #DIV/0! | N13: =M13/$M$15 -> #DIV/0!
B14: RENDA VARIAVEL | D14: =B33 -> 0 | E14: =D14/$E$15 -> #DIV/0! | L14: Renda Variavel | M14: =D14 -> 0 | N14: =M14/$M$15 -> #DIV/0!
C15: Total da Carteira Nasser Family ==> | E15: =SUM(D4:D14) -> 0 | M15: =SUM(M4:M14) -> 0 | N15: =SUM(N4:N14) -> #DIV/0!
B18: ANALISE % Alocação da Carteira "Nasser Family" RENDA VARIAVEL(06/2023)
C19: % Renda Variavel Alocadas por Setor
B20: =+'Planilha de Rentabilidade'!Z46 -> 0 | C20: =B20/$B$33 -> #DIV/0! | D20: IRON ORE
B21: =+'Planilha de Rentabilidade'!O46 -> 0 | C21: =B21/$B$33 -> #DIV/0! | D21: SOJA
B22: =+'Planilha de Rentabilidade'!U46+'Planilha de Rentabilidade'!AB46+'Planilha de Rentabilidade'!AF46 -> 0 | C22: =B22/$B$33 -> #DIV/0! | D22: Electric Vehicle
B23: 0 | C23: =B23/$B$33 -> #DIV/0! | D23: Tec.NVIDIA
B24: 0 | C24: =B24/$B$33 -> #DIV/0! | D24: LITHIUM
B25: ='Planilha de Rentabilidade'!AE46 -> 0 | C25: =B25/$B$33 -> #DIV/0! | D25: FINANCEIRO
B26: ='Planilha de Rentabilidade'!R46 -> 0 | C26: =B26/$B$33 -> #DIV/0! | D26: CELULOSE
B27: 0 | C27: =B27/$B$33 -> #DIV/0! | D27: Saude
B28: 0 | C28: =B28/$B$33 -> #DIV/0! | D28: Comodites_GOLD
B29: =+'Planilha de Rentabilidade'!X46+'Planilha de Rentabilidade'!Y46 -> 0 | C29: =B29/$B$33 -> #DIV/0! | D29: ASML
B30: =+'Planilha de Rentabilidade'!T46+'Planilha de Rentabilidade'!AG46 -> 0 | C30: =B30/$B$33 -> #DIV/0! | D30: APPLE
B31: =+'Planilha de Rentabilidade'!AH46+'Planilha de Rentabilidade'!N46 -> 0 | C31: =B31/$B$33 -> #DIV/0! | D31: INTEL
B32: 0 | C32: =B32/$B$33 -> #DIV/0! | D32: CARROCERIAS ONIBUS
B33: =SUM(B20:B32) -> 0 | C33: =B33/$B$33 -> #DIV/0!

Sheet % de Alocação da Carteira 07_25
B2: ANALISE % de Alocação da Carteira "Nasser Family"p/ Produto Financeiro (07/2023) | M2: ALOCAÇÃO % COMPACTA
E3: =+SUM(E4:E12) -> #DIV/0!
B4: CAIXA | D4: =+'Planilha de Rentabilidade'!E54 -> 0 | E4: =D4/$E$15 -> #DIV/0! | L4: IPCA + | M4: =+D5+D6 -> 0 | N4: =M4/$M$15 -> #DIV/0!
B5: TD IPCA+2029 | D5: =+'Planilha de Rentabilidade'!Q54 -> 0 | E5: =D5/$E$15 -> #DIV/0! | N5: =M5/$M$15 -> #DIV/0!
B6: DEBENTURE IPCA+7,60% | D6: =+'Planilha de Rentabilidade'!P54 -> 0 | E6: =D6/$E$15 -> #DIV/0! | N6: =M6/$M$15 -> #DIV/0!
B7: CRI CRA | D7: 0 | E7: =D7/$E$15 -> #DIV/0! | L7: FUNDOS | M7: =+D12 -> 0 | N7: =M7/$M$15 -> #DIV/0!
B8: TD SELIC+LFTS11 | D8: =+'Planilha de Rentabilidade'!C54+'Planilha de Rentabilidade'!D54+'Planilha de Rentabilidade'!F54 -> 0 | E8: =D8/$E$15 -> #DIV/0! | L8: RENDA FIXA | M8: =+D8+D13 -> 0 | N8: =M8/$M$15 -> #DIV/0!
B9: MOEDAS | D9: =+'Planilha de Rentabilidade'!L54 -> 0 | E9: =D9/$E$15 -> #DIV/0! | L9: $$ | M9: =+D9+D10 -> 0 | N9: =M9/$M$15 -> #DIV/0!
B10: GOLD + $$$ | D10: =+'Planilha de Rentabilidade'!M54 -> 0 | E10: =D10/$E$15 -> #DIV/0! | M10: 0 | N10: =M10/$M$15 -> #DIV/0!
B11: LCA | D11: 0 | E11: =D11/$E$15 -> #DIV/0! | N11: =M11/$M$15 -> #DIV/0!
B12: FUNDO DI | D12: =+'Planilha de Rentabilidade'!G54+'Planilha de Rentabilidade'!I54+'Planilha de Rentabilidade'!J54 -> 0 | E12: =D12/$E$15 -> #DIV/0! | L12: CAIXA | M12: =+D4 -> 0 | N12: =M12/$M$15 -> #DIV/0!
B13: CDB DI | D13: =+'Planilha de Rentabilidade'!H54+'Planilha de Rentabilidade'!K54+'Planilha de Rentabilidade'!S54+'Planilha de Rentabilidade'!V54 -> 0 | E13: =D13/$E$15 -> #DIV/0! | N13: =M13/$M$15 -> #DIV/0!
B14: RENDA VARIAVEL | D14: =B33 -> 0 | E14: =D14/$E$15 -> #DIV/0! | L14: Renda Variavel | M14: =D14 -> 0 | N14: =M14/$M$15 -> #DIV/0!
C15: Total da Carteira Nasser Family ==> | E15: =SUM(D4:D14) -> 0 | M15: =SUM(M4:M14) -> 0 | N15: =SUM(N4:N14) -> #DIV/0!
B18: ANALISE % Alocação da Carteira "Nasser Family" RENDA VARIAVEL(07/2023)
C19: % Renda Variavel Alocadas por Setor
B20: =+'Planilha de Rentabilidade'!Z54+'Planilha de Rentabilidade'!W54 -> 0 | C20: =B20/$B$33 -> #DIV/0! | D20: IRON ORE
B21: =+'Planilha de Rentabilidade'!O54 -> 0 | C21: =B21/$B$33 -> #DIV/0! | D21: SOJA
A22: CC | B22: =+'Planilha de Rentabilidade'!U54+'Planilha de Rentabilidade'!AB54+'Planilha de Rentabilidade'!AF54 -> 0 | C22: =B22/$B$33 -> #DIV/0! | D22: Electric Vehicle
A23: FN | B23: 0 | C23: =B23/$B$33 -> #DIV/0! | D23: Tec.NVIDIA
A24: CM | B24: 0 | C24: =B24/$B$33 -> #DIV/0! | D24: LITHIUM
A25: SD | B25: ='Planilha de Rentabilidade'!AE54+'Planilha de Rentabilidade'!AD54 -> 0 | C25: =B25/$B$33 -> #DIV/0! | D25: FINANCEIRO
A26: GD | B26: ='Planilha de Rentabilidade'!R54 -> 0 | C26: =B26/$B$33 -> #DIV/0! | D26: CELULOSE
A27: EN | B27: 0 | C27: =B27/$B$33 -> #DIV/0! | D27: Saude
A28: VR | B28: 0 | C28: =B28/$B$33 -> #DIV/0! | D28: Comodites_GOLD
A29: TC | B29: =+'Planilha de Rentabilidade'!X54+'Planilha de Rentabilidade'!Y54 -> 0 | C29: =B29/$B$33 -> #DIV/0! | D29: ASML
A30: SN | B30: =+'Planilha de Rentabilidade'!T54+'Planilha de Rentabilidade'!AG54 -> 0 | C30: =B30/$B$33 -> #DIV/0! | D30: APPLE
B31: =+'Planilha de Rentabilidade'!AH54+'Planilha de Rentabilidade'!N54 -> 0 | C31: =B31/$B$33 -> #DIV/0! | D31: INTEL
B32: 0 | C32: =B32/$B$33 -> #DIV/0! | D32: CARROCERIAS ONIBUS
B33: =SUM(B20:B32) -> 0 | C33: =B33/$B$33 -> #DIV/0!

Sheet % de Alocação da Carteira 08_25
B2: ANALISE % de Alocação da Carteira "Nasser Family"p/ Produto Financeiro (08/2023) | L2: 45505 | M2: ALOCAÇÃO % COMPACTA
E3: =+SUM(E4:E14) -> #DIV/0!
B4: CAIXA | D4: =+'Planilha de Rentabilidade'!E62 -> 0 | E4: =D4/$E$15 -> #DIV/0! | L4: IPCA + | M4: =+D5+D6 -> 0 | N4: =M4/$M$15 -> #DIV/0!
B5: TD IPCA+2029 | D5: =+'Planilha de Rentabilidade'!Q62 -> 0 | E5: =D5/$E$15 -> #DIV/0! | N5: =M5/$M$15 -> #DIV/0!
B6: DEBENTURE IPCA+7,60% | D6: =+'Planilha de Rentabilidade'!P62 -> 0 | E6: =D6/$E$15 -> #DIV/0! | N6: =M6/$M$15 -> #DIV/0!
B7: CRI CRA | D7: 0 | E7: =D7/$E$15 -> #DIV/0! | L7: FUNDOS | M7: =+D12 -> 0 | N7: =M7/$M$15 -> #DIV/0!
B8: TD SELIC+LFTS11 | D8: =+'Planilha de Rentabilidade'!C62+'Planilha de Rentabilidade'!D62+'Planilha de Rentabilidade'!F62 -> 0 | E8: =D8/$E$15 -> #DIV/0! | L8: RENDA FIXA | M8: =+D8+D13 -> 0 | N8: =M8/$M$15 -> #DIV/0!
B9: MOEDAS | D9: =+'Planilha de Rentabilidade'!L62 -> 0 | E9: =D9/$E$15 -> #DIV/0! | L9: $$ | M9: =+D9+D10 -> 0 | N9: =M9/$M$15 -> #DIV/0!
B10: GOLD + $$$ | D10: =+'Planilha de Rentabilidade'!M62 -> 0 | E10: =D10/$E$15 -> #DIV/0! | M10: 0 | N10: =M10/$M$15 -> #DIV/0!
B11: LCA | D11: 0 | E11: =D11/$E$15 -> #DIV/0! | N11: =M11/$M$15 -> #DIV/0!
B12: FUNDO DI | D12: =+'Planilha de Rentabilidade'!G62+'Planilha de Rentabilidade'!I62+'Planilha de Rentabilidade'!J62 -> 0 | E12: =D12/$E$15 -> #DIV/0! | L12: CAIXA | M12: =+D4 -> 0 | N12: =M12/$M$15 -> #DIV/0!
B13: CDB DI | D13: =+'Planilha de Rentabilidade'!H62+'Planilha de Rentabilidade'!K62+'Planilha de Rentabilidade'!S62+'Planilha de Rentabilidade'!V62 -> 0 | E13: =D13/$E$15 -> #DIV/0! | N13: =M13/$M$15 -> #DIV/0!
B14: RENDA VARIAVEL | D14: =B33 -> 0 | E14: =D14/$E$15 -> #DIV/0! | L14: Renda Variavel | M14: =D14 -> 0 | N14: =M14/$M$15 -> #DIV/0!
C15: Total da Carteira Nasser Family ==> | E15: =SUM(D4:D14) -> 0 | M15: =SUM(M4:M14) -> 0 | N15: =SUM(N4:N14) -> #DIV/0!
B18: ANALISE % Alocação da Carteira "Nasser Family"RENDA VARIAVEL(08/2023)
C19: % Renda Variavel Alocadas por Setor
B20: =+'Planilha de Rentabilidade'!Z62+'Planilha de Rentabilidade'!W62 -> 0 | C20: =B20/$B$33 -> #DIV/0! | D20: IRON ORE
B21: =+'Planilha de Rentabilidade'!O62 -> 0 | C21: =B21/$B$33 -> #DIV/0! | D21: SOJA
B22: =+'Planilha de Rentabilidade'!U62+'Planilha de Rentabilidade'!AF62 -> 0 | C22: =B22/$B$33 -> #DIV/0! | D22: Electric Vehicle
B23: 0 | C23: =B23/$B$33 -> #DIV/0! | D23: Tec.NVIDIA
B24: =+'Planilha de Rentabilidade'!AA62 -> 0 | C24: =B24/$B$33 -> #DIV/0! | D24: LITHIUM
B25: 0 | C25: =B25/$B$33 -> #DIV/0! | D25: FINANCEIRO
B26: 0 | C26: =B26/$B$33 -> #DIV/0! | D26: CELULOSE
B27: 0 | C27: =B27/$B$33 -> #DIV/0! | D27: Saude
B28: 0 | C28: =B28/$B$33 -> #DIV/0! | D28: Comodites_GOLD
B29: =+'Planilha de Rentabilidade'!X62+'Planilha de Rentabilidade'!Y62 -> 0 | C29: =B29/$B$33 -> #DIV/0! | D29: ASML
B30: =+'Planilha de Rentabilidade'!T62+'Planilha de Rentabilidade'!AG62 -> 0 | C30: =B30/$B$33 -> #DIV/0! | D30: APPLE
B31: =+'Planilha de Rentabilidade'!AH62+'Planilha de Rentabilidade'!N62 -> 0 | C31: =B31/$B$33 -> #DIV/0! | D31: INTEL
B32: ='Planilha de Rentabilidade'!AB62 -> 0 | C32: =B32/$B$33 -> #DIV/0! | D32: WEGE
B33: =SUM(B20:B32) -> 0 | C33: =B33/$B$33 -> #DIV/0!

Sheet % de Alocação da Carteira 09_25
B2: ANALISE % de Alocação da Carteira "Nasser Family"p/ Produto Financeiro (09/2023) | M2: ALOCAÇÃO % COMPACTA
E3: =+SUM(E4:E14) -> #DIV/0!
B4: CAIXA | D4: ='Planilha de Rentabilidade'!E70 -> 0 | E4: =D4/$E$15 -> #DIV/0! | L4: IPCA + | M4: =SUM(D5:D7) -> 0 | N4: =M4/$M$15 -> #DIV/0!
B5: TESOURO IPCA+2035 | D5: 0 | E5: =D5/$E$15 -> #DIV/0! | M5: 0 | N5: =M5/$M$15 -> #DIV/0!
B6: DEBENTURE | D6: ='Planilha de Rentabilidade'!P70 -> 0 | E6: =D6/$E$15 -> #DIV/0! | M6: 0 | N6: =M6/$M$15 -> #DIV/0!
B7: CRI CRA | D7: 0 | E7: =D7/$E$15 -> #DIV/0! | L7: LCA | M7: =+D11 -> 0 | N7: =M7/$M$15 -> #DIV/0!
B8: TESOURO SELIC + LFTS11 | D8: ='Planilha de Rentabilidade'!C70+'Planilha de Rentabilidade'!D70+'Planilha de Rentabilidade'!Q70+'Planilha de Rentabilidade'!F70 -> 0 | E8: =D8/$E$15 -> #DIV/0! | L8: RENDA FIXA | M8: =D8+D12+D13 -> 0 | N8: =M8/$M$15 -> #DIV/0!
B9: MOEDAS | D9: ='Planilha de Rentabilidade'!L70 -> 0 | E9: =D9/$E$15 -> #DIV/0! | L9: GOLD + $$ | M9: =+D10 -> 0 | N9: =M9/$M$15 -> #DIV/0!
B10: GOLD + $$$ | D10: ='Planilha de Rentabilidade'!M70 -> 0 | E10: =D10/$E$15 -> #DIV/0! | L10: MOEDAS | M10: =D9 -> 0 | N10: =M10/$M$15 -> #DIV/0!
B11: LCA | D11: 0 | E11: =D11/$E$15 -> #DIV/0! | N11: =M11/$M$15 -> #DIV/0!
B12: FUNDO DI | D12: ='Planilha de Rentabilidade'!G70+'Planilha de Rentabilidade'!I70+'Planilha de Rentabilidade'!J70 -> 0 | E12: =D12/$E$15 -> #DIV/0! | L12: CAIXA | M12: =+D4 -> 0 | N12: =M12/$M$15 -> #DIV/0!
B13: RENDA FIXA CDB DI | D13: ='Planilha de Rentabilidade'!K70 -> 0 | E13: =D13/$E$15 -> #DIV/0! | N13: =M13/$M$15 -> #DIV/0!
B14: RENDA VARIAVEL | D14: =B33 -> 0 | E14: =D14/$E$15 -> #DIV/0! | L14: R.V. | M14: =D14 -> 0 | N14: =M14/$M$15 -> #DIV/0!
C15: Total da Carteira Nasser Family ==> | E15: =SUM(D4:D14) -> 0 | M15: =SUM(M4:M14) -> 0 | N15: =SUM(N4:N14) -> #DIV/0!
B18: ANALISE % Alocação da Carteira "Nasser Family" RENDA VARIAVEL(09/2023)
C19: % Renda Variavel Alocadas por Setor
B20: ='Planilha de Rentabilidade'!Z70+'Planilha de Rentabilidade'!AD70+'Planilha de Rentabilidade'!W70 -> 0 | C20: =B20/$B$33 -> #DIV/0! | D20: IRON ORE
B21: 0 | C21: =B21/$B$33 -> #DIV/0! | D21: SOJA
B22: ='Planilha de Rentabilidade'!U70+'Planilha de Rentabilidade'!AF70 -> 0 | C22: =B22/$B$33 -> #DIV/0! | D22: Electric Vehicle
B23: ='Planilha de Rentabilidade'!F70 -> 0 | C23: =B23/$B$33 -> #DIV/0! | D23: Tec.NVIDIA
B24: ='Planilha de Rentabilidade'!AA70+'Planilha de Rentabilidade'!AE70 -> 0 | C24: =B24/$B$33 -> #DIV/0! | D24: LITHIUM
B25: 0 | C25: =B25/$B$33 -> #DIV/0! | D25: FINANCEIRO
B26: ='Planilha de Rentabilidade'!R70+'Planilha de Rentabilidade'!AC70 -> 0 | C26: =B26/$B$33 -> #DIV/0! | D26: CELULOSE
B27: 0 | C27: =B27/$B$33 -> #DIV/0! | D27: Saude
B28: 0 | C28: =B28/$B$33 -> #DIV/0! | D28: Comodites_GOLD
B29: ='Planilha de Rentabilidade'!X70+'Planilha de Rentabilidade'!Y70 -> 0 | C29: =B29/$B$33 -> #DIV/0! | D29: ASML
B30: ='Planilha de Rentabilidade'!AG70+'Planilha de Rentabilidade'!T70 -> 0 | C30: =B30/$B$33 -> #DIV/0! | D30: APPLE
B31: ='Planilha de Rentabilidade'!AH70+'Planilha de Rentabilidade'!N70 -> 0 | C31: =B31/$B$33 -> #DIV/0! | D31: INTEL
